Workbook

Sheet Assumptions
A1: LEVELING SYSTEM — CORE ASSUMPTIONS
A2: Parameter | B2: Symbol | C2: Value | D2: Notes
A3: EXP req exponent | B3: α | C3: 1.65 | D3: Fixed across all stages and tracks
A4: EXP req constant (Awakened) | B4: C_req | C4: 100 | D4: Blue = input. Shifts at stage transition.
A5: Kill yield exponent | B5: β | C5: 1.35 | D5: Fixed across all stages and tracks
A6: Kill yield constant (Awakened) | B6: C_kill | C6: 10 | D6: Blue = input. Shifts at stage transition.
A7: Class EXP share (aligned) | B7: — | C7: 0.6 | D7: Fully aligned kill method
A8: Race EXP share (aligned) | B8: — | C8: 0.4 | D8: Fully aligned kill method
A9: Class EXP share (partial) | B9: — | C9: 0.2 | D9: Partially aligned kill method
A10: Race EXP share (partial) | B10: — | C10: 0.8 | D10: Partially aligned kill method
A11: Class EXP share (unaligned) | B11: — | C11: 0 | D11: Unaligned kill method
A12: Race EXP share (unaligned) | B12: — | C12: 1 | D12: Unaligned kill method
A13: Kill shot bonus | B13: — | C13: 0.4 | D13: +40% on top of contribution share
A14: Faction EXP split (class) | B14: — | C14: 0.35 | D14: Faction/leadership actions
... A16: Non-qualifying gate yield | B16: — | C16: 0.05 | D16: 5% of normal yield during narrative gate
A17: Blue values = inputs that can be changed. All other sheets reference these cells.

Sheet Rank & Level Structure
A1: RANK & LEVEL STRUCTURE
A2: Rank | B2: Class Lv range | C2: Class Lv cap | D2: Overall class Lv | E2: Sublimation stage | F2: Race Lv pool | G2: Combined peak
A3: F | B3: [1–10] | C3: 10 | D3: 10 | E3: Awakened | F3: 50 | G3: 60
A4: E | B4: [1–15] | C4: 15 | D4: 25 | E4: Awakened | F4: 50 | G4: 75
A5: D | B5: [1–25] | C5: 25 | D5: 50 | E5: Awakened | F5: 50 | G5: 100
A6: C | B6: [1–40] | C6: 40 | D6: 90 | E6: Extraordinary | F6: 100 | G6: 190
A7: B | B7: [1–60] | C7: 60 | D7: 150 | E7: Extraordinary | F7: 100 | G7: 250
A8: A | B8: [1–70] | C8: 70 | D8: 220 | E8: Named | F8: 150 | G8: 370
A9: S | B9: [1–80] | C9: 80 | D9: 300 | E9: Named | F9: 150 | G9: 450
A10: SS | B10: [1–200] | C10: 200 | D10: 500 | E10: Eternal | F10: 200 | G10: 700
A11: EX | B11: [1–∞] | C11: ∞ | D11: ∞ | E11: Primordial | F11: ∞ | G11: ∞
A13: Race level pool is shared freely across all ranks within a stage — no sub-cap per rank.

Sheet EXP Required
A1: EXP REQUIRED PER LEVEL | Formula: Lv^α × C_req
A2: α = Assumptions!C3 C_req = Assumptions!C4 (change assumptions there)
A3: Track level (x) | B3: Rank | C3: EXP req (x→x+1) | D3: Cumulative class EXP
A4: 1 | B4: F | C4: =1^Assumptions!$C$3*Assumptions!$C$4 -> 100 | D4: =C4 -> 100
A5: 2 | B5: F | C5: =2^Assumptions!$C$3*Assumptions!$C$4 -> 313.83364 | D5: =D4+C5 -> 413.83364
A6: 3 | B6: F | C6: =3^Assumptions!$C$3*Assumptions!$C$4 -> 612.70309 | D6: =D5+C6 -> 1026.5367
A7: 4 | B7: F | C7: =4^Assumptions!$C$3*Assumptions!$C$4 -> 984.91553 | D7: =D6+C7 -> 2011.4523
A8: 5 | B8: F | C8: =5^Assumptions!$C$3*Assumptions!$C$4 -> 1423.3133 | D8: =D7+C8 -> 3434.7656
A9: 6 | B9: F | C9: =6^Assumptions!$C$3*Assumptions!$C$4 -> 1922.8684 | D9: =D8+C9 -> 5357.634
A10: 7 | B10: F | C10: =7^Assumptions!$C$3*Assumptions!$C$4 -> 2479.7721 | D10: =D9+C10 -> 7837.406
A11: 8 | B11: F | C11: =8^Assumptions!$C$3*Assumptions!$C$4 -> 3090.9963 | D11: =D10+C11 -> 10928.402
A12: 9 | B12: F | C12: =9^Assumptions!$C$3*Assumptions!$C$4 -> 3754.0508 | D12: =D11+C12 -> 14682.453
A13: 10 | B13: F | C13: =10^Assumptions!$C$3*Assumptions!$C$4 -> 4466.8359 | D13: =D12+C13 -> 19149.289
A14: 11 | B14: E | C14: =11^Assumptions!$C$3*Assumptions!$C$4 -> 5227.5468 | D14: =D13+C14 -> 24376.836
A15: 12 | B15: E | C15: =12^Assumptions!$C$3*Assumptions!$C$4 -> 6034.6079 | D15: =D14+C15 -> 30411.444
A16: 13 | B16: E | C16: =13^Assumptions!$C$3*Assumptions!$C$4 -> 6886.6265 | D16: =D15+C16 -> 37298.07
A17: 14 | B17: E | C17: =14^Assumptions!$C$3*Assumptions!$C$4 -> 7782.359 | D17: =D16+C17 -> 45080.429
A18: 15 | B18: E | C18: =15^Assumptions!$C$3*Assumptions!$C$4 -> 8720.6846 | D18: =D17+C18 -> 53801.114
A19: 16 | B19: E | C19: =16^Assumptions!$C$3*Assumptions!$C$4 -> 9700.586 | D19: =D18+C19 -> 63501.7
A20: 17 | B20: E | C20: =17^Assumptions!$C$3*Assumptions!$C$4 -> 10721.134 | D20: =D19+C20 -> 74222.834
A21: 18 | B21: E | C21: =18^Assumptions!$C$3*Assumptions!$C$4 -> 11781.474 | D21: =D20+C21 -> 86004.308
A22: 19 | B22: E | C22: =19^Assumptions!$C$3*Assumptions!$C$4 -> 12880.818 | D22: =D21+C22 -> 98885.126
A23: 20 | B23: E | C23: =20^Assumptions!$C$3*Assumptions!$C$4 -> 14018.434 | D23: =D22+C23 -> 112903.56
A24: 21 | B24: E | C24: =21^Assumptions!$C$3*Assumptions!$C$4 -> 15193.64 | D24: =D23+C24 -> 128097.2
A25: 22 | B25: E | C25: =22^Assumptions!$C$3*Assumptions!$C$4 -> 16405.8 | D25: =D24+C25 -> 144503
A26: 23 | B26: E | C26: =23^Assumptions!$C$3*Assumptions!$C$4 -> 17654.317 | D26: =D25+C26 -> 162157.32
A27: 24 | B27: E | C27: =24^Assumptions!$C$3*Assumptions!$C$4 -> 18938.63 | D27: =D26+C27 -> 181095.95
A28: 25 | B28: E | C28: =25^Assumptions!$C$3*Assumptions!$C$4 -> 20258.207 | D28: =D27+C28 -> 201354.15
A29: 26 | B29: D | C29: =26^Assumptions!$C$3*Assumptions!$C$4 -> 21612.551 | D29: =D28+C29 -> 222966.7
A30: 27 | B30: D | C30: =27^Assumptions!$C$3*Assumptions!$C$4 -> 23001.185 | D30: =D29+C30 -> 245967.89
A31: 28 | B31: D | C31: =28^Assumptions!$C$3*Assumptions!$C$4 -> 24423.66 | D31: =D30+C31 -> 270391.55
A32: 30 | B32: D | C32: =30^Assumptions!$C$3*Assumptions!$C$4 -> 27368.442 | D32: =D31+C32 -> 297759.99
A33: 35 | B33: D | C33: =35^Assumptions!$C$3*Assumptions!$C$4 -> 35294.926 | D33: =D32+C33 -> 333054.92
A34: 40 | B34: D | C34: =40^Assumptions!$C$3*Assumptions!$C$4 -> 43994.561 | D34: =D33+C34 -> 377049.48
A35: 45 | B35: D | C35: =45^Assumptions!$C$3*Assumptions!$C$4 -> 53431.904 | D35: =D34+C35 -> 430481.38
A36: 50 | B36: D | C36: =50^Assumptions!$C$3*Assumptions!$C$4 -> 63577.07 | D36: =D35+C36 -> 494058.45
A42: Cumulative EXP resets at each sublimation stage boundary. C_req recalibrates — see Stage Transition sheet.

Sheet Kill EXP Cross Table
A1: KILL EXP CROSS TABLE | Your overall Lv (rows) vs Opponent overall Lv (cols) | Same rank, factor ×1.0
A2: Formula: Opp_Lv^β × C_kill × (Opp_Lv / Your_Lv) | β = Assumptions!C5 C_kill = Assumptions!C6
A3: Your Lv \ Opp Lv | B3: 1 | C3: 2 | D3: 3 | E3: 4 | F3: 5 | G3: 6 | H3: 7 | I3: 8 | J3: 9 | K3: 10 | L3: 12 | M3: 14 | N3: 16 | O3: 18 | P3: 20 | Q3: 25 | R3: 30 | S3: 40 | T3: 50 | U3: 75 | V3: 100
A4: 1 | B4: 10 | C4: 51 | D4: 132 | E4: 260 | F4: 439 | G4: 674 | H4: 968 | I4: 1325 | J4: 1748 | K4: 2239 | L4: 3436 | M4: 4936 | N4: 6756 | O4: 8910 | P4: 11414 | Q4: 19282 | R4: 29596 | S4: 58189 | T4: 98306 | U4: 254914 | V4: 501187
A5: 2 | B5: 5 | C5: 25 | D5: 66 | E5: 130 | F5: 220 | G5: 337 | H5: 484 | I5: 663 | J5: 874 | K5: 1119 | L5: 1718 | M5: 2468 | N5: 3378 | O5: 4455 | P5: 5707 | Q5: 9641 | R5: 14798 | S5: 29095 | T5: 49153 | U5: 127457 | V5: 250594
A6: 3 | B6: 3 | C6: 17 | D6: 44 | E6: 87 | F6: 146 | G6: 225 | H6: 323 | I6: 442 | J6: 583 | K6: 746 | L6: 1145 | M6: 1645 | N6: 2252 | O6: 2970 | P6: 3805 | Q6: 6427 | R6: 9865 | S6: 19396 | T6: 32769 | U6: 84971 | V6: 167062
A7: 4 | B7: 2 | C7: 13 | D7: 33 | E7: 65 | F7: 110 | G7: 168 | H7: 242 | I7: 331 | J7: 437 | K7: 560 | L7: 859 | M7: 1234 | N7: 1689 | O7: 2228 | P7: 2853 | Q7: 4821 | R7: 7399 | S7: 14547 | T7: 24576 | U7: 63729 | V7: 125297
A8: 5 | B8: 2 | C8: 10 | D8: 26 | E8: 52 | F8: 88 | G8: 135 | H8: 194 | I8: 265 | J8: 350 | K8: 448 | L8: 687 | M8: 987 | N8: 1351 | O8: 1782 | P8: 2283 | Q8: 3856 | R8: 5919 | S8: 11638 | T8: 19661 | U8: 50983 | V8: 100237
A9: 6 | B9: 2 | C9: 8 | D9: 22 | E9: 43 | F9: 73 | G9: 112 | H9: 161 | I9: 221 | J9: 291 | K9: 373 | L9: 573 | M9: 823 | N9: 1126 | O9: 1485 | P9: 1902 | Q9: 3214 | R9: 4933 | S9: 9698 | T9: 16384 | U9: 42486 | V9: 83531
A10: 7 | B10: 1 | C10: 7 | D10: 19 | E10: 37 | F10: 63 | G10: 96 | H10: 138 | I10: 189 | J10: 250 | K10: 320 | L10: 491 | M10: 705 | N10: 965 | O10: 1273 | P10: 1631 | Q10: 2755 | R10: 4228 | S10: 8313 | T10: 14044 | U10: 36416 | V10: 71598
A11: 8 | B11: 1 | C11: 6 | D11: 17 | E11: 32 | F11: 55 | G11: 84 | H11: 121 | I11: 166 | J11: 218 | K11: 280 | L11: 430 | M11: 617 | N11: 844 | O11: 1114 | P11: 1427 | Q11: 2410 | R11: 3700 | S11: 7274 | T11: 12288 | U11: 31864 | V11: 62648
A12: 9 | B12: 1 | C12: 6 | D12: 15 | E12: 29 | F12: 49 | G12: 75 | H12: 108 | I12: 147 | J12: 194 | K12: 249 | L12: 382 | M12: 548 | N12: 751 | O12: 990 | P12: 1268 | Q12: 2142 | R12: 3288 | S12: 6465 | T12: 10923 | U12: 28324 | V12: 55687
A13: 10 | B13: 1 | C13: 5 | D13: 13 | E13: 26 | F13: 44 | G13: 67 | H13: 97 | I13: 133 | J13: 175 | K13: 224 | L13: 344 | M13: 494 | N13: 676 | O13: 891 | P13: 1141 | Q13: 1928 | R13: 2960 | S13: 5819 | T13: 9831 | U13: 25491 | V13: 50119
A14: 12 | B14: 1 | C14: 4 | D14: 11 | E14: 22 | F14: 37 | G14: 56 | H14: 81 | I14: 110 | J14: 146 | K14: 187 | L14: 286 | M14: 411 | N14: 563 | O14: 743 | P14: 951 | Q14: 1607 | R14: 2466 | S14: 4849 | T14: 8192 | U14: 21243 | V14: 41766
A15: 14 | B15: 1 | C15: 4 | D15: 9 | E15: 19 | F15: 31 | G15: 48 | H15: 69 | I15: 95 | J15: 125 | K15: 160 | L15: 245 | M15: 353 | N15: 483 | O15: 636 | P15: 815 | Q15: 1377 | R15: 2114 | S15: 4156 | T15: 7022 | U15: 18208 | V15: 35799
... A24: 100 | B24: 0 | C24: 1 | D24: 1 | E24: 3 | F24: 4 | G24: 7 | H24: 10 | I24: 13 | J24: 17 | K24: 22 | L24: 34 | M24: 49 | N24: 68 | O24: 89 | P24: 114 | Q24: 193 | R24: 296 | S24: 582 | T24: 983 | U24: 2549 | V24: 5012
A26: Blue bold = over-level kill (opp > you) | Red = under-level kill (opp < you) | Black = same level
A27: This table shows same-rank kills only (factor ×1.0). Multiply by rank factor for over-rank: ×2.0 (+1 rank), ×3.5 (+2 ranks), ×5.0 (+3 ranks).
A28: Values hardcoded at β=1.35, C_kill=10 (Awakened baseline). Recalculate manually if assumptions change.

Sheet kill exp cross table 2
A1: KILL EXP CROSS TABLE | Your overall Lv (rows) vs Opponent overall Lv (cols) | Same rank, factor ×1.0
A2: Formula: Opp_Lv^β × C_kill × (Opp_Lv / Your_Lv) | β = Assumptions!C5 C_kill = Assumptions!C6
A3: Your Lv \ Opp Lv | B3: 1 | C3: 2 | D3: 3 | E3: 4 | F3: 5 | G3: 6 | H3: 7 | I3: 8 | J3: 9 | K3: 10 | L3: 12 | M3: 14 | N3: 16 | O3: 18 | P3: 20 | Q3: 25 | R3: 30 | S3: 40 | T3: 50 | U3: 75 | V3: 100
A4: 1 | B4: =(B$3/$A4)*Assumptions!$C$6*B$3^Assumptions!$C$5 -> 10 | C4: =(C$3/$A4)*Assumptions!$C$6*C$3^Assumptions!$C$5 -> 50.982425 | D4: =(D$3/$A4)*Assumptions!$C$6*D$3^Assumptions!$C$5 -> 132.20106 | E4: =(E$3/$A4)*Assumptions!$C$6*E$3^Assumptions!$C$5 -> 259.92077 | F4: =(F$3/$A4)*Assumptions!$C$6*F$3^Assumptions!$C$5 -> 439.11625 | G4: =(G$3/$A4)*Assumptions!$C$6*G$3^Assumptions!$C$5 -> 673.99308 | H4: =(H$3/$A4)*Assumptions!$C$6*H$3^Assumptions!$C$5 -> 968.23414 | I4: =(I$3/$A4)*Assumptions!$C$6*I$3^Assumptions!$C$5 -> 1325.1391 | ... V4: =(V$3/$A4)*Assumptions!$C$6*V$3^Assumptions!$C$5 -> 501187.23
A5: 2 | B5: =(B$3/$A5)*Assumptions!$C$6*B$3^Assumptions!$C$5 -> 5 | C5: =(C$3/$A5)*Assumptions!$C$6*C$3^Assumptions!$C$5 -> 25.491213 | D5: =(D$3/$A5)*Assumptions!$C$6*D$3^Assumptions!$C$5 -> 66.100532 | E5: =(E$3/$A5)*Assumptions!$C$6*E$3^Assumptions!$C$5 -> 129.96038 | F5: =(F$3/$A5)*Assumptions!$C$6*F$3^Assumptions!$C$5 -> 219.55813 | G5: =(G$3/$A5)*Assumptions!$C$6*G$3^Assumptions!$C$5 -> 336.99654 | H5: =(H$3/$A5)*Assumptions!$C$6*H$3^Assumptions!$C$5 -> 484.11707 | I5: =(I$3/$A5)*Assumptions!$C$6*I$3^Assumptions!$C$5 -> 662.56955 | ... V5: =(V$3/$A5)*Assumptions!$C$6*V$3^Assumptions!$C$5 -> 250593.62
A6: 3 | B6: =(B$3/$A6)*Assumptions!$C$6*B$3^Assumptions!$C$5 -> 3.3333333 | C6: =(C$3/$A6)*Assumptions!$C$6*C$3^Assumptions!$C$5 -> 16.994142 | D6: =(D$3/$A6)*Assumptions!$C$6*D$3^Assumptions!$C$5 -> 44.067021 | E6: =(E$3/$A6)*Assumptions!$C$6*E$3^Assumptions!$C$5 -> 86.640256 | F6: =(F$3/$A6)*Assumptions!$C$6*F$3^Assumptions!$C$5 -> 146.37208 | G6: =(G$3/$A6)*Assumptions!$C$6*G$3^Assumptions!$C$5 -> 224.66436 | H6: =(H$3/$A6)*Assumptions!$C$6*H$3^Assumptions!$C$5 -> 322.74471 | I6: =(I$3/$A6)*Assumptions!$C$6*I$3^Assumptions!$C$5 -> 441.71303 | ... V6: =(V$3/$A6)*Assumptions!$C$6*V$3^Assumptions!$C$5 -> 167062.41
A7: 4 | B7: =(B$3/$A7)*Assumptions!$C$6*B$3^Assumptions!$C$5 -> 2.5 | C7: =(C$3/$A7)*Assumptions!$C$6*C$3^Assumptions!$C$5 -> 12.745606 | D7: =(D$3/$A7)*Assumptions!$C$6*D$3^Assumptions!$C$5 -> 33.050266 | E7: =(E$3/$A7)*Assumptions!$C$6*E$3^Assumptions!$C$5 -> 64.980192 | F7: =(F$3/$A7)*Assumptions!$C$6*F$3^Assumptions!$C$5 -> 109.77906 | G7: =(G$3/$A7)*Assumptions!$C$6*G$3^Assumptions!$C$5 -> 168.49827 | H7: =(H$3/$A7)*Assumptions!$C$6*H$3^Assumptions!$C$5 -> 242.05854 | I7: =(I$3/$A7)*Assumptions!$C$6*I$3^Assumptions!$C$5 -> 331.28478 | ... V7: =(V$3/$A7)*Assumptions!$C$6*V$3^Assumptions!$C$5 -> 125296.81
A8: 5 | B8: =(B$3/$A8)*Assumptions!$C$6*B$3^Assumptions!$C$5 -> 2 | C8: =(C$3/$A8)*Assumptions!$C$6*C$3^Assumptions!$C$5 -> 10.196485 | D8: =(D$3/$A8)*Assumptions!$C$6*D$3^Assumptions!$C$5 -> 26.440213 | E8: =(E$3/$A8)*Assumptions!$C$6*E$3^Assumptions!$C$5 -> 51.984153 | F8: =(F$3/$A8)*Assumptions!$C$6*F$3^Assumptions!$C$5 -> 87.82325 | G8: =(G$3/$A8)*Assumptions!$C$6*G$3^Assumptions!$C$5 -> 134.79862 | H8: =(H$3/$A8)*Assumptions!$C$6*H$3^Assumptions!$C$5 -> 193.64683 | I8: =(I$3/$A8)*Assumptions!$C$6*I$3^Assumptions!$C$5 -> 265.02782 | ... V8: =(V$3/$A8)*Assumptions!$C$6*V$3^Assumptions!$C$5 -> 100237.45
A9: 6 | B9: =(B$3/$A9)*Assumptions!$C$6*B$3^Assumptions!$C$5 -> 1.6666667 | C9: =(C$3/$A9)*Assumptions!$C$6*C$3^Assumptions!$C$5 -> 8.4970708 | D9: =(D$3/$A9)*Assumptions!$C$6*D$3^Assumptions!$C$5 -> 22.033511 | E9: =(E$3/$A9)*Assumptions!$C$6*E$3^Assumptions!$C$5 -> 43.320128 | F9: =(F$3/$A9)*Assumptions!$C$6*F$3^Assumptions!$C$5 -> 73.186042 | G9: =(G$3/$A9)*Assumptions!$C$6*G$3^Assumptions!$C$5 -> 112.33218 | H9: =(H$3/$A9)*Assumptions!$C$6*H$3^Assumptions!$C$5 -> 161.37236 | I9: =(I$3/$A9)*Assumptions!$C$6*I$3^Assumptions!$C$5 -> 220.85652 | ... V9: =(V$3/$A9)*Assumptions!$C$6*V$3^Assumptions!$C$5 -> 83531.206
A10: 7 | B10: =(B$3/$A10)*Assumptions!$C$6*B$3^Assumptions!$C$5 -> 1.4285714 | C10: =(C$3/$A10)*Assumptions!$C$6*C$3^Assumptions!$C$5 -> 7.2832036 | D10: =(D$3/$A10)*Assumptions!$C$6*D$3^Assumptions!$C$5 -> 18.885866 | E10: =(E$3/$A10)*Assumptions!$C$6*E$3^Assumptions!$C$5 -> 37.131538 | F10: =(F$3/$A10)*Assumptions!$C$6*F$3^Assumptions!$C$5 -> 62.730893 | G10: =(G$3/$A10)*Assumptions!$C$6*G$3^Assumptions!$C$5 -> 96.284726 | H10: =(H$3/$A10)*Assumptions!$C$6*H$3^Assumptions!$C$5 -> 138.31916 | I10: =(I$3/$A10)*Assumptions!$C$6*I$3^Assumptions!$C$5 -> 189.30559 | ... V10: =(V$3/$A10)*Assumptions!$C$6*V$3^Assumptions!$C$5 -> 71598.176
A11: 8 | B11: =(B$3/$A11)*Assumptions!$C$6*B$3^Assumptions!$C$5 -> 1.25 | C11: =(C$3/$A11)*Assumptions!$C$6*C$3^Assumptions!$C$5 -> 6.3728031 | D11: =(D$3/$A11)*Assumptions!$C$6*D$3^Assumptions!$C$5 -> 16.525133 | E11: =(E$3/$A11)*Assumptions!$C$6*E$3^Assumptions!$C$5 -> 32.490096 | F11: =(F$3/$A11)*Assumptions!$C$6*F$3^Assumptions!$C$5 -> 54.889531 | G11: =(G$3/$A11)*Assumptions!$C$6*G$3^Assumptions!$C$5 -> 84.249135 | H11: =(H$3/$A11)*Assumptions!$C$6*H$3^Assumptions!$C$5 -> 121.02927 | I11: =(I$3/$A11)*Assumptions!$C$6*I$3^Assumptions!$C$5 -> 165.64239 | ... V11: =(V$3/$A11)*Assumptions!$C$6*V$3^Assumptions!$C$5 -> 62648.404
A12: 9 | B12: =(B$3/$A12)*Assumptions!$C$6*B$3^Assumptions!$C$5 -> 1.1111111 | C12: =(C$3/$A12)*Assumptions!$C$6*C$3^Assumptions!$C$5 -> 5.6647139 | D12: =(D$3/$A12)*Assumptions!$C$6*D$3^Assumptions!$C$5 -> 14.689007 | E12: =(E$3/$A12)*Assumptions!$C$6*E$3^Assumptions!$C$5 -> 28.880085 | F12: =(F$3/$A12)*Assumptions!$C$6*F$3^Assumptions!$C$5 -> 48.790695 | G12: =(G$3/$A12)*Assumptions!$C$6*G$3^Assumptions!$C$5 -> 74.88812 | H12: =(H$3/$A12)*Assumptions!$C$6*H$3^Assumptions!$C$5 -> 107.58157 | I12: =(I$3/$A12)*Assumptions!$C$6*I$3^Assumptions!$C$5 -> 147.23768 | ... V12: =(V$3/$A12)*Assumptions!$C$6*V$3^Assumptions!$C$5 -> 55687.47
A13: 10 | B13: =(B$3/$A13)*Assumptions!$C$6*B$3^Assumptions!$C$5 -> 1 | C13: =(C$3/$A13)*Assumptions!$C$6*C$3^Assumptions!$C$5 -> 5.0982425 | D13: =(D$3/$A13)*Assumptions!$C$6*D$3^Assumptions!$C$5 -> 13.220106 | E13: =(E$3/$A13)*Assumptions!$C$6*E$3^Assumptions!$C$5 -> 25.992077 | F13: =(F$3/$A13)*Assumptions!$C$6*F$3^Assumptions!$C$5 -> 43.911625 | G13: =(G$3/$A13)*Assumptions!$C$6*G$3^Assumptions!$C$5 -> 67.399308 | H13: =(H$3/$A13)*Assumptions!$C$6*H$3^Assumptions!$C$5 -> 96.823414 | I13: =(I$3/$A13)*Assumptions!$C$6*I$3^Assumptions!$C$5 -> 132.51391 | ... V13: =(V$3/$A13)*Assumptions!$C$6*V$3^Assumptions!$C$5 -> 50118.723
A14: 12 | B14: =(B$3/$A14)*Assumptions!$C$6*B$3^Assumptions!$C$5 -> 0.83333333 | C14: =(C$3/$A14)*Assumptions!$C$6*C$3^Assumptions!$C$5 -> 4.2485354 | D14: =(D$3/$A14)*Assumptions!$C$6*D$3^Assumptions!$C$5 -> 11.016755 | E14: =(E$3/$A14)*Assumptions!$C$6*E$3^Assumptions!$C$5 -> 21.660064 | F14: =(F$3/$A14)*Assumptions!$C$6*F$3^Assumptions!$C$5 -> 36.593021 | G14: =(G$3/$A14)*Assumptions!$C$6*G$3^Assumptions!$C$5 -> 56.16609 | H14: =(H$3/$A14)*Assumptions!$C$6*H$3^Assumptions!$C$5 -> 80.686179 | I14: =(I$3/$A14)*Assumptions!$C$6*I$3^Assumptions!$C$5 -> 110.42826 | ... V14: =(V$3/$A14)*Assumptions!$C$6*V$3^Assumptions!$C$5 -> 41765.603
A15: 14 | B15: =(B$3/$A15)*Assumptions!$C$6*B$3^Assumptions!$C$5 -> 0.71428571 | C15: =(C$3/$A15)*Assumptions!$C$6*C$3^Assumptions!$C$5 -> 3.6416018 | D15: =(D$3/$A15)*Assumptions!$C$6*D$3^Assumptions!$C$5 -> 9.4429331 | E15: =(E$3/$A15)*Assumptions!$C$6*E$3^Assumptions!$C$5 -> 18.565769 | F15: =(F$3/$A15)*Assumptions!$C$6*F$3^Assumptions!$C$5 -> 31.365447 | G15: =(G$3/$A15)*Assumptions!$C$6*G$3^Assumptions!$C$5 -> 48.142363 | H15: =(H$3/$A15)*Assumptions!$C$6*H$3^Assumptions!$C$5 -> 69.159582 | I15: =(I$3/$A15)*Assumptions!$C$6*I$3^Assumptions!$C$5 -> 94.652793 | ... V15: =(V$3/$A15)*Assumptions!$C$6*V$3^Assumptions!$C$5 -> 35799.088
... A24: 100 | B24: =(B$3/$A24)*Assumptions!$C$6*B$3^Assumptions!$C$5 -> 0.1 | C24: =(C$3/$A24)*Assumptions!$C$6*C$3^Assumptions!$C$5 -> 0.50982425 | D24: =(D$3/$A24)*Assumptions!$C$6*D$3^Assumptions!$C$5 -> 1.3220106 | E24: =(E$3/$A24)*Assumptions!$C$6*E$3^Assumptions!$C$5 -> 2.5992077 | F24: =(F$3/$A24)*Assumptions!$C$6*F$3^Assumptions!$C$5 -> 4.3911625 | G24: =(G$3/$A24)*Assumptions!$C$6*G$3^Assumptions!$C$5 -> 6.7399308 | H24: =(H$3/$A24)*Assumptions!$C$6*H$3^Assumptions!$C$5 -> 9.6823414 | I24: =(I$3/$A24)*Assumptions!$C$6*I$3^Assumptions!$C$5 -> 13.251391 | ... V24: =(V$3/$A24)*Assumptions!$C$6*V$3^Assumptions!$C$5 -> 5011.8723
A26: Blue bold = over-level kill (opp > you) | Red = under-level kill (opp < you) | Black = same level
A27: This table shows same-rank kills only (factor ×1.0). Multiply by rank factor for over-rank: ×2.0 (+1 rank), ×3.5 (+2 ranks), ×5.0 (+3 ranks).
A28: Values hardcoded at β=1.35, C_kill=10 (Awakened baseline). Recalculate manually if assumptions change.

Sheet Kill EXP Calculator
A1: KILL EXP CALCULATOR | Solo and Team scenarios
A2: Yellow cells = inputs. Quality gap is determined automatically from Self quality vs Opponent quality.
A3: SHARED INPUTS
A4: Your overall level | B4: 10
A5: Opponent overall level | B5: 10
A6: Rank factor | B6: 1
A7: Alignment (1=full / 0.5=partial / 0=unaligned) | B7: 1
A8: Self quality | B8: Basic | C8: ← quality: Basic / Elite / Rare / Epic / Apex / Legendary / Celestial
A9: Opponent quality | B9: Elite | C9: ← quality: Basic / Elite / Rare / Epic / Apex / Legendary / Celestial
A10: Quality gap (auto) | B10: =MAX(0,IF(B9="Basic",0,IF(B9="Elite",1,IF(B9="Rare",2,IF(B9="Epic",3,IF(B9="Apex",4,IF(B9="Legendary",5,6))))))-IF(B8="Basic",0,IF(B8="Elite",1,IF(B8="Rare",2,IF(B8="Epic",3,IF(B8="Apex",4,IF(B8="Legendary",5,6))))))) -> 1 | C10: ← auto from qualities above
A11: Rank factor ref: same=×1.0 | +1 rank=×2.0 | +2=×3.5 | +3=×5.0 | +4=×6.5 | below=×0
A13: SOLO KILL | F13: TEAM KILL
A14: Base kill EXP | B14: =B5^Assumptions!C5*Assumptions!C6*B6*(B5/B4) -> 223.87211 | F14: Team inputs
A15: Quality gap bonus % | B15: =IF(B10=0,0,IF(B10=1,0.45,IF(B10=2,1.1,IF(B10=3,2,IF(B10=4,3.2,IF(B10=5,4.75,4.75+(B10-5)*1.8)))))) -> 0.45 | F15: Number of contributors | G15: 3
A16: Quality flat base | B16: =IF(B9="Basic",0,IF(B9="Elite",70,IF(B9="Rare",175,IF(B9="Epic",470,IF(B9="Apex",1170,IF(B9="Legendary",2920,4670+(MATCH(B9,{"Basic","Elite","Rare","Epic","Apex","Legendary","Celestial"},0)-6)*1750)))))) -> 70 | F16: Your contribution % | G16: 0.5
A17: Quality flat (scaled) | B17: =IF(B10>0,B16*(B5/10),0) -> 70 | F17: Kill shot? (1=yes 0=no) | G17: 1
A18: Quality bonus pool | B18: =IF(B10>0,B14*B15+B17,0) -> 170.74245 | F18: Team quality floor | G18: Basic | H18: ← team floor = highest contributing member quality
A19: Class EXP (base) | B19: =B14*IF(B7=1,Assumptions!C7,IF(B7=0.5,Assumptions!C9,Assumptions!C11)) -> 134.32327 | F19: Quality gap (team, auto) | G19: =MAX(0,IF(B9="Basic",0,IF(B9="Elite",1,IF(B9="Rare",2,IF(B9="Epic",3,IF(B9="Apex",4,IF(B9="Legendary",5,6))))))-IF(G18="Basic",0,IF(G18="Elite",1,IF(G18="Rare",2,IF(G18="Epic",3,IF(G18="Apex",4,IF(G18="Legendary",5,6))))))) -> 1 | H19: ← auto from opp quality vs team floor
A20: Race EXP (base) | B20: =B14*IF(B7=1,Assumptions!C8,IF(B7=0.5,Assumptions!C10,Assumptions!C12)) -> 89.548846
A21: Quality bonus → class | B21: =B18*IF(B7=1,Assumptions!C7,IF(B7=0.5,Assumptions!C9,Assumptions!C11)) -> 102.44547 | F21: Team calculation
A22: Quality bonus → race | B22: =B18*IF(B7=1,Assumptions!C8,IF(B7=0.5,Assumptions!C10,Assumptions!C12)) -> 68.29698 | F22: Base kill EXP (same formula) | G22: =B14 -> 223.87211
A23: TOTAL class EXP | B23: =B19+B21 -> 236.76874 | F23: Your base share (contribution) | G23: =G22*G16 -> 111.93606
A24: TOTAL race EXP | B24: =B20+B22 -> 157.84583 | F24: Kill shot bonus | G24: =IF(G17=1,G23*Assumptions!C13,0) -> 44.774423
F25: Team quality flat base | G25: =IF(G18="Basic",0,IF(G19=0,0,IF(B9="Elite",70,IF(B9="Rare",175,IF(B9="Epic",470,IF(B9="Apex",1170,IF(B9="Legendary",2920,4670))))))) -> 0
A26: Solo summary | F26: Team quality flat scaled | G26: =IF(G19>0,G25*(B5/10),0) -> 0
A27: Total class EXP | B27: =B23 -> 236.76874 | F27: Team quality gap % | G27: =IF(G19=0,0,IF(G19=1,0.45,IF(G19=2,1.1,IF(G19=3,2,IF(G19=4,3.2,IF(G19=5,4.75,4.75+(G19-5)*1.8)))))) -> 0.45
A28: Total race EXP | B28: =B24 -> 157.84583 | F28: Team quality bonus pool | G28: =IF(G19>0,G22*G27+G26,0) -> 100.74245
A29: Grand total | B29: =B23+B24 -> 394.61457 | F29: Your quality share | G29: =G28*G16 -> 50.371226
F30: Your total EXP (pre-split) | G30: =G23+G24+G29 -> 207.08171
F31: Your class EXP | G31: =G30*IF(B7=1,Assumptions!C7,IF(B7=0.5,Assumptions!C9,Assumptions!C11)) -> 124.24902
F32: Your race EXP | G32: =G30*IF(B7=1,Assumptions!C8,IF(B7=0.5,Assumptions!C10,Assumptions!C12)) -> 82.832682
F34: Team summary (your share)
F35: Your class EXP | G35: =G31 -> 124.24902
F36: Your race EXP | G36: =G32 -> 82.832682
F37: Your grand total | G37: =G31+G32 -> 207.08171
A39: RANK FACTOR REFERENCE
A40: Gap | B40: Factor | C40: Description
A41: Below rank | B41: ×0 | C41: Hard zero
A42: Same rank | B42: ×1.0 | C42: Baseline
A43: +1 rank | B43: ×2.0 | C43: Adjacent letter boundary
...

Sheet Quality Bonus Table
A1: QUALITY BONUS — GAP BONUS & FLAT UNLOCK TABLE
A2: Gap bonus (% of base kill EXP post rank factor) | E2: Flat unlock (base value — scaled by opp overall Lv/10)
A3: Quality gap (tiers) | B3: Gap bonus % | C3: Increment | E3: Opponent quality | F3: Base flat | G3: Increment
A4: 0 | B4: 0% | C4: — | E4: Basic (no bonus) | F4: 0 | G4: —
A5: 1 | B5: 45% | C5: +45% | E5: Elite | F5: 70 | G5: +70
A6: 2 | B6: 110% | C6: +65% | E6: Rare | F6: 175 | G6: +105
A7: 3 | B7: 200% | C7: +90% | E7: Epic | F7: 470 | G7: +295
A8: 4 | B8: 320% | C8: +120% | E8: Apex | F8: 1170 | G8: +700
A9: 5 | B9: 475% | C9: +155% | E9: Legendary | F9: 2920 | G9: +1,750
A10: 6 | B10: 655% | C10: +180% per tier | E10: Celestial+ | F10: 4670 | G10: +1,750 per tier
A12: Actual flat bonus = Base flat × (opponent overall Lv / 10). Bloodline uses identical table and stacks independently.

Sheet EXP Modifiers
A1: EXP MODIFIERS — SKILLS / TITLES / TALENTS
A2: Modifier source ranges
A3: Source | B3: EXP req reduction (min) | C3: EXP req reduction (max) | D3: Kill yield boost (min) | E3: Kill yield boost (max) | F3: Gate
A4: Skill | B4: 0.02 | C4: 0.08 | D4: 0.05 | E4: 0.15 | F4: Level threshold
A5: Title | B5: 0.05 | C5: 0.2 | D5: 0.1 | E5: 0.3 | F5: Achievement
A6: Talent | B6: 0.1 | C6: 0.35 | D6: 0.15 | E6: 0.5 | F6: Innate / progressive
A8: Soft cap — EXP requirement reduction
A9: Zone | B9: Raw total range | C9: Efficiency | D9: Description
A10: Free zone | B10: 0% – 30% | C10: 100% | D10: Full effect — every % applies at face value
A11: Soft cap | B11: 30% – 60% | C11: 50% | D11: Each additional % costs 2% of modifier value
A12: Hard ceiling | B12: 60%+ | C12: 0% | D12: No further reduction possible
A14: Effective reduction calculator
A15: Raw total reduction (sum of all modifiers) | B15: 0.3
A16: Effective reduction | B16: =IF(B15<=0.3,B15,MIN(0.6,0.3+(B15-0.3)*0.5)) -> 0.3
A17: Kill yield boost (no cap — enter total) | B17: 0.53
A19: Jay — modifier stack (Book 1 provisional)
A20: Source | B20: Type | C20: EXP req reduction | D20: Kill yield boost | E20: Gate | F20: Notes
A21: Primal Spirit Orb | B21: Talent | C21: -0.13 | D21: 0.2 | E21: Active from Ascension | F21: Low-mid Talent range. Edge from spirits, not EXP.
A22: First over-rank kill | B22: Title | C22: -0.08 | D22: 0.15 | E22: Achievement
A23: Faction founder | B23: Title | C23: -0.05 | D23: 0.1 | E23: Achievement
A24: Class skill (TBD) | B24: Skill | C24: -0.04 | D24: 0.08 | E24: Level threshold
A25: Raw total | B25: -0.3 | C25: 0.53
A26: Effective (after soft cap) | B26: =IF(-0.3<=-0.3,-0.3,MIN(-0.6,-0.3+(-0.3+0.3)*0.5)) -> -0.3 | C26: 0.53

Sheet Non-Kill EXP Sources
A1: NON-KILL EXP SOURCES & ROUTING
A2: Source | B2: Efficiency (min) | C2: Efficiency (max) | D2: Track routing | E2: Class split | F2: Race split | G2: Notes
A3: Crafting / non-combat skills | B3: 0.5 | C3: 0.7 | D3: Class only | E3: 1 | F3: 0 | G3: Crafter classes can progress without combat.
A4: Faction / leadership actions | B4: 0.3 | C4: 0.5 | D4: Split (35/65) | E4: 0.35 | F4: 0.65 | G4: Authority shapes being more than class.
A5: Training / deliberate practice | B5: 0.2 | C5: 0.35 | D5: Class only | E5: 1 | F5: 0 | G5: No race benefit — body needs real stress.
A6: Exploration / discovery | B6: 0.1 | C6: 0.2 | D6: Race only | E6: 0 | F6: 1 | G6: New environments accelerate sublimation.
A8: Diminishing returns apply to repeated actions. The System rewards genuine novelty — farming the same action yields progressively less.
A10: KILL METHOD ALIGNMENT — EXP SPLIT
A11: Alignment tier | B11: Definition | C11: Class share | D11: Race share | E11: Example
A12: Fully aligned | B12: Kill through core class method | C12: 0.6 | D12: 0.4 | E12: Warrior kills with sword
A13: Partially aligned | B13: Hybrid — class involved but secondary | C13: 0.2 | D13: 0.8 | E13: Warrior uses sword + finishes with gun
A14: Unaligned | B14: Kill entirely outside class identity | C14: 0 | D14: 1 | E14: Warrior kills with gun only

Sheet Stage Transition
A1: SUBLIMATION STAGE TRANSITION — C_kill & C_req RECALIBRATION
A2: β and α stay fixed. Only C_kill and C_req shift at each boundary. Each track computes independently.
A3: Transition formulas
A4: new_C_kill | B4: =D10*(D8+1)^Assumptions!C5 -> 5079.6508 | D4: Uses opponent OVERALL level (class + race). Same axis as yield formula.
A5: new_C_req | B5: =D11*(D9+1)^Assumptions!C3 -> 65688.719 | D5: Uses character's own TRACK PEAK local level. Each track independent.
A7: Worked example — Awakened → Extraordinary
A8: Stage entry overall level (opponent axis — class + race peak) | D8: 100
A9: Track peak local level (character axis — per track) | D9: 50
A10: C_kill (Awakened) | D10: =Assumptions!C6 -> 10
A11: C_req (Awakened) | D11: =Assumptions!C4 -> 100
A12: new_C_kill = C_kill × (overall_lv + 1)^β | D12: =D10*(D8+1)^Assumptions!$C$5 -> 5079.6508
A13: new_C_req = C_req × (track_peak + 1)^α | D13: =D11*(D9+1)^Assumptions!$C$3 -> 65688.719
A15: Verification — Lv1 of new stage matches continuous curve
A16: Kill yield — new stage Lv1 | B16: =1^Assumptions!$C$5*D12 -> 5079.6508 | C16: Kill yield — continuous Lv(track_peak+1) | D16: =(D9+1)^Assumptions!$C$5*Assumptions!$C$6 -> 2019.3878 | E16: ✓ should match
A17: EXP req — new stage Lv1 | B17: =1^Assumptions!$C$3*D13 -> 65688.719 | C17: EXP req — continuous Lv(track_peak+1) | D17: =(D9+1)^Assumptions!$C$3*Assumptions!$C$4 -> 65688.719 | E17: ✓ should match

Sheet FA & Skill Thresholds
A1: FREE ATTRIBUTE POINTS & SKILL UNLOCK THRESHOLDS
A2: Race track — FA per level-up (primary source)
A3: Sublimation stage | B3: Rank equivalent | C3: FA per race lv-up (min) | D3: FA per race lv-up (max)
A4: Awakened | B4: F / E / D | C4: 15 | D4: 25
A5: Extraordinary | B5: C / B | C5: 30 | D5: 50
A6: Named | B6: A / S | C6: 60 | D6: 100
A7: Eternal | B7: SS | C7: TBD | D7: TBD
A9: Class track — FA bonus per level-up (secondary source)
A10: Class quality | B10: Rank F FA/lv | C10: Rank E FA/lv | D10: Rank D FA/lv | E10: Notes
A11: Basic | B11: 1–2 | C11: 2–3 | D11: 3–5 | E11: Minimal. Race track carries the load.
A12: Elite | B12: 2–3 | C12: 3–5 | D12: 5–7 | E12: Noticeable step up.
A13: Rare | B13: 3–5 | C13: 5–8 | D13: 7–11 | E13: Meaningful divergence begins.
A14: Epic | B14: 5–7 | C14: 7–11 | D14: 10–15 | E14: Class track becomes a genuine contributor.
A15: Apex | B15: 7–10 | C15: 10–15 | D15: 14–20 | E15: Rivals lower race FA ranges.
A17: Skill unlock thresholds — Rank F & E
A18: Rank | B18: Class level | C18: Unlock | D18: Quality minimum | E18: Notes
A19: F | B19: Lv 5 | C19: First skill slot | D19: Basic+ | E19: Weak — reflects early state
A20: F | B20: Lv 8 | C20: First slot → Elite upgrade | D20: Elite+ | E20: Basic class stays Basic
A21: F | B21: Lv 10 | C21: Second skill slot | D21: Basic+ | E21: Narrative gate active
A22: F | B22: Lv 13 | C22: Second slot → Elite upgrade | D22: Elite+
A23: F | B23: Lv 15 | C23: Rank-up gate + class advancement | D23: Basic+ | E23: Class quality minimum enforced
A24: E | B24: Lv 5 | C24: Third skill slot | D24: Basic+ | E24: First new slot post rank-up
A25: E | B25: Lv 10 | C25: Slot upgrade window | D25: Elite+ | E25: Can upgrade any existing slot
A26: E | B26: Lv 15 | C26: Fourth skill slot | D26: Rare+ | E26: Rare+ unlocks higher quality
A27: E | B27: Lv 20 | C27: Second upgrade window | D27: Elite+ | E27: Narrative gate active
A28: E | B28: Lv 25 | C28: Rank-up gate + class advancement | D28: Elite+ | E28: Rare minimum enforced for D
